<?xml version="1.0"?>
<gazebo version="1.4">
  <model name="pioneer3dx">
    <link name="chassis">
      <pose>0 0 0.16 0 0 0</pose>
      <inertial>
        <mass>5.0</mass>
      </inertial>
      <collision name="collision">
        <geometry>
          <box>
            <size>0.445 0.277 0.17</size>
          </box>
        </geometry>
      </collision>
      <collision name="castor_collision">
        <pose>-0.200 0 -0.12 0 0 0</pose>
        <geometry>
          <sphere>
            <radius>0.04</radius>
          </sphere>
        </geometry>
        <surface>
          <friction>
            <ode>
              <mu>0</mu>
              <mu2>0</mu2>
              <slip1>1.0</slip1>
              <slip2>1.0</slip2>
            </ode>
          </friction>
        </surface>
      </collision>
      <visual name="visual">
        <pose>0 0 0.04 0 0 0</pose>
        <geometry>
          <mesh>
            <uri>model://pioneer2dx/meshes/chassis.dae</uri>
          </mesh>
        </geometry>
      </visual>
      <visual name="castor_visual">
        <pose>-0.200 0 -0.12 0 0 0</pose>
        <geometry>
          <sphere>
            <radius>0.04</radius>
          </sphere>
        </geometry>
        <material>
          <script>
            <uri>file://media/materials/scripts/gazebo.material</uri>
            <name>Gazebo/FlatBlack</name>
          </script>
        </material>
      </visual>
    </link>
    <link name="right_wheel">
      <pose>0.1 -.17 0.11 0 1.5707 1.5707</pose>
      <inertial>
        <mass>0.1</mass>
      </inertial>
      <collision name="collision">
        <geometry>
          <cylinder>
            <radius>0.11</radius>
            <length>0.05</length>
          </cylinder>
        </geometry>
        <surface>
          <friction>
            <ode>
              <mu>100000.0</mu>
              <mu2>100000.0</mu2>
              <slip1>0.0</slip1>
              <slip2>0.0</slip2>
            </ode>
          </friction>
        </surface>
      </collision>
      <visual name="visual">
        <geometry>
          <cylinder>
            <radius>0.11</radius>
            <length>0.05</length>
          </cylinder>
        </geometry>
        <material>
          <script>
            <uri>file://media/materials/scripts/gazebo.material</uri>
            <name>Gazebo/FlatBlack</name>
          </script>
        </material>
      </visual>
    </link>
    <link name="left_wheel">
      <pose>0.1 .17 0.11 0 1.5707 1.5707</pose>
      <inertial>
        <mass>0.5</mass>
      </inertial>
      <collision name="collision">
        <geometry>
          <cylinder>
            <radius>0.11</radius>
            <length>0.05</length>
          </cylinder>
        </geometry>
        <surface>
          <friction>
            <ode>
              <mu>100000.0</mu>
              <mu2>100000.0</mu2>
              <slip1>0.0</slip1>
              <slip2>0.0</slip2>
            </ode>
          </friction>
        </surface>
      </collision>
      <visual name="visual">
        <geometry>
          <cylinder>
            <radius>0.11</radius>
            <length>0.05</length>
          </cylinder>
        </geometry>
        <material>
          <script>
            <uri>file://media/materials/scripts/gazebo.material</uri>
            <name>Gazebo/FlatBlack</name>
          </script>
        </material>
      </visual>
    </link>
<link name="camera_link"> 
	<pose>0 0 0.4 0 0 0</pose>
	<inertial>
		 <mass>0.1</mass> 
	</inertial> 
	<collision name="collision"> 
		<geometry>
			<box> 
				<size>0.073000 0.276000 0.072000</size>
			</box> 
		</geometry> 
	</collision> 
	<visual name="visual">
		
		<geometry> 
			<box> 
				<size>0.073000 0.276000 0.072000</size>
			</box> 
		</geometry>
	</visual>
	<!-- camera -->
    <sensor type="depth" name="camera">
      <update_rate>60.0</update_rate>
      <camera name="head">
        <horizontal_fov>1.3962634</horizontal_fov>
        <image>
          <width>800</width>
          <height>800</height>
          <format>R8G8B8</format>
        </image>
        <clip>
          <near>0.02</near>
          <far>300</far>
        </clip>
        <noise>
          <type>gaussian</type>
          <!-- Noise is sampled independently per pixel on each frame.
               That pixel's noise value is added to each of its color
               channels, which at that point lie in the range [0,1]. -->
          <mean>0.0</mean>
          <stddev>0.007</stddev>
        </noise>
      </camera>
      <plugin name="camera_link_controller" filename="libgazebo_ros_openni_kinect.so">
    <baseline>0.2</baseline>
    <alwaysOn>true</alwaysOn>
    <updateRate>60</updateRate>
    <cameraName>camera_ir</cameraName>
    <imageTopicName>/camera/depth/image_raw</imageTopicName>
    <cameraInfoTopicName>/camera/depth/camera_info</cameraInfoTopicName>
    <depthImageTopicName>/camera/depth/depth_raw</depthImageTopicName>
    <depthImageInfoTopicName>/camera/depth/camera_info</depthImageInfoTopicName>
    <pointCloudTopicName>/camera/depth/points</pointCloudTopicName>
    <frameName>base_footprint</frameName>
    <pointCloudCutoff>0.5</pointCloudCutoff>
    <distortionK1>0.00000001</distortionK1>
    <distortionK2>0.00000001</distortionK2>
    <distortionK3>0.00000001</distortionK3>
    <distortionT1>0.00000001</distortionT1>
    <distortionT2>0.00000001</distortionT2>
    <CxPrime>0</CxPrime>
    <Cx>0</Cx>
    <Cy>0</Cy>
    <focalLength>0</focalLength>
    <hackBaseline>0</hackBaseline>
  </plugin> 
    </sensor>
</link>

    <joint type="revolute" name="left_wheel_hinge">
      <pose>0 0 -0.03 0 0 0</pose>
      <child>left_wheel</child>
      <parent>chassis</parent>
      <axis>
        <xyz>0 1 0</xyz>
      </axis>
    </joint>

    <joint type="revolute" name="right_wheel_hinge">
      <pose>0 0 0.03 0 0 0</pose>
      <child>right_wheel</child>
      <parent>chassis</parent>
      <axis>
        <xyz>0 1 0</xyz>
      </axis>
    </joint>

    <joint name="camera_joint" type="revolute">
      <child>camera_link</child>
      <parent>chassis</parent>
      <axis>
      <xyz>0 0 1</xyz>
      <limit>
        <upper>0</upper>
        <lower>0</lower>
      </limit>
    </axis>
     </joint>
<plugin name="differential_drive_controller" filename="libgazebo_ros_diff_drive.so">
        <alwaysOn>true</alwaysOn>
        <updateRate>10</updateRate>
        <leftJoint>right_wheel_hinge</leftJoint>
        <rightJoint>left_wheel_hinge</rightJoint>
        <wheelSeparation>0.277</wheelSeparation>
        <wheelDiameter>0.10</wheelDiameter>
        <torque>5</torque>
        <commandTopic>cmd_vel</commandTopic>
        <odometryTopic>odom</odometryTopic>
        <odometryFrame>odom</odometryFrame>
        <robotBaseFrame>base_link</robotBaseFrame>
</plugin>
 
   

  </model>
</gazebo>
